<?xml version='1.0' encoding='utf-8'?>
<robot name="adam_sp_hands">
  <!-- 左手手腕 -->
  <link name="LeftHand">
    <inertial>
      <origin xyz="-0.00027229 0.00864497 -0.06627017" rpy="0 0 0" />
      <mass value="0.35749661" />
      <inertia ixx="0.00032014" ixy="0.00001166" ixz="-0.00000403" iyy="0.00042954" iyz="-0.00002167" izz="0.00018487" />
    </inertial>
    <visual>
      <origin xyz="0 0 0" rpy="0 0 0" />
      <geometry>
        <mesh filename="meshes/wristRollLeft.STL" />
      </geometry>
      <material name="">
        <color rgba="0.752941176470588 0.752941176470588 0.752941176470588 1" />
      </material>
    </visual>
    <collision>
      <origin xyz="0 0 0" rpy="0 0 0" />
      <geometry>
        <mesh filename="meshes/wristRollLeft.STL" />
      </geometry>
    </collision>
  </link>

  <!-- 左手拇指 -->
  <link name="L_thumb_proximal_base">
    <inertial>
      <origin xyz="0.00431634 0.00026726 -0.00141885" rpy="0 0 0" />
      <mass value="0.00893190" />
      <inertia ixx="0.00000031" ixy="-0.00000008" ixz="-0.00000006" iyy="0.00000055" iyz="0.00000001" izz="0.00000046" />
    </inertial>
    <visual>
      <origin xyz="0 0 0" rpy="0 0 0" />
      <geometry>
        <mesh filename="meshes/L_thumb_proximal_base.STL" />
      </geometry>
      <material name="">
        <color rgba="0.752941176470588 0.752941176470588 0.752941176470588 1" />
      </material>
    </visual>
    <collision>
      <origin xyz="0 0 0" rpy="0 0 0" />
      <geometry>
        <mesh filename="meshes/L_thumb_proximal_base.STL" />
      </geometry>
    </collision>
  </link>
  <joint name="L_thumb_MCP_joint1" type="revolute">
    <origin xyz="0.0244999999969742 -0.0099999999982788 -0.0470000000019433" rpy="0 0 0" />
    <parent link="LeftHand" />
    <child link="L_thumb_proximal_base" />
    <axis xyz="0 0 -1" />
    <limit lower="0" upper="1.1" effort="1" velocity="1" />
  </joint>
  <link name="L_thumb_proximal">
    <inertial>
      <origin xyz="0.02369693 0.00000000 -0.01467236" rpy="0 0 0" />
      <mass value="0.06158427" />
      <inertia ixx="0.00001171" ixy="0.00000000" ixz="-0.00000575" iyy="0.00002013" iyz="0.00000000" izz="0.00001139" />
    </inertial>
    <visual>
      <origin xyz="0 0 0" rpy="0 0 0" />
      <geometry>
        <mesh filename="meshes/L_thumb_proximal.STL" />
      </geometry>
      <material name="">
        <color rgba="0.752941176470588 0.752941176470588 0.752941176470588 1" />
      </material>
    </visual>
    <collision>
      <origin xyz="0 0 0" rpy="0 0 0" />
      <geometry>
        <mesh filename="meshes/L_thumb_proximal.STL" />
      </geometry>
    </collision>
  </link>
  <joint name="L_thumb_MCP_joint2" type="revolute">
    <origin xyz="0.011954002456522 -0.00104967865057148 0" rpy="0 0 -0.0875851578962738" />
    <parent link="L_thumb_proximal_base" />
    <child link="L_thumb_proximal" />
    <axis xyz="0 1 0" />
    <limit lower="0" upper="0.5" effort="1" velocity="1" />
  </joint>
  <link name="L_thumb_intermediate">
    <inertial>
      <origin xyz="0.00973134 0.00000000 -0.00266466" rpy="0 0 0" />
      <mass value="0.01538337" />
      <inertia ixx="0.00000142" ixy="0.00000000" ixz="-0.00000039" iyy="0.00000172" iyz="0.00000000" izz="0.00000100" />
    </inertial>
    <visual>
      <origin xyz="0 0 0" rpy="0 0 0" />
      <geometry>
        <mesh filename="meshes/L_thumb_intermediate.STL" />
      </geometry>
      <material name="">
        <color rgba="0.752941176470588 0.752941176470588 0.752941176470588 1" />
      </material>
    </visual>
    <collision>
      <origin xyz="0 0 0" rpy="0 0 0" />
      <geometry>
        <mesh filename="meshes/L_thumb_intermediate.STL" />
      </geometry>
    </collision>
  </link>
  <joint name="L_thumb_PIP_joint" type="revolute">
    <origin xyz="0.0442885641132063 0 -0.0376632856876562" rpy="0 0 0" />
    <parent link="L_thumb_proximal" />
    <child link="L_thumb_intermediate" />
    <axis xyz="0 1 0" />
    <limit lower="0" upper="1" effort="1" velocity="1" />
  </joint>
  <link name="L_thumb_distal">
    <inertial>
      <origin xyz="0.00714221 -0.00000154 -0.00689404" rpy="0 0 0" />
      <mass value="0.01043740" />
      <inertia ixx="0.00000076" ixy="0.00000000" ixz="-0.00000020" iyy="0.00000086" iyz="0.00000000" izz="0.00000052" />
    </inertial>
    <visual>
      <origin xyz="0 0 0" rpy="0 0 0" />
      <geometry>
        <mesh filename="meshes/L_thumb_distal.STL" />
      </geometry>
      <material name="">
        <color rgba="0.752941176470588 0.752941176470588 0.752941176470588 1" />
      </material>
    </visual>
    <collision>
      <origin xyz="0 0 0" rpy="0 0 0" />
      <geometry>
        <mesh filename="meshes/L_thumb_distal.STL" />
      </geometry>
    </collision>
  </link>
  <joint name="L_thumb_DIP_joint" type="revolute">
    <origin xyz="0.0164679343341741 0 -0.0154614727230483" rpy="0 0 0" />
    <parent link="L_thumb_intermediate" />
    <child link="L_thumb_distal" />
    <axis xyz="0 1 0" />
    <limit lower="0" upper="1.2" effort="1" velocity="1" />
  </joint>

  <!-- 左手食指 -->
  <link name="L_index_proximal">
    <inertial>
      <origin xyz="0.00000000 0.00199817 -0.01311708" rpy="0 0 0" />
      <mass value="0.01454111" />
      <inertia ixx="0.00000195" ixy="0.00000000" ixz="0.00000000" iyy="0.00000195" iyz="0.00000002" izz="0.00000054" />
    </inertial>
    <visual>
      <origin xyz="0 0 0" rpy="0 0 0" />
      <geometry>
        <mesh filename="meshes/L_index_proximal.STL" />
      </geometry>
      <material name="">
        <color rgba="0.752941176470588 0.752941176470588 0.752941176470588 1" />
      </material>
    </visual>
    <collision>
      <origin xyz="0 0 0" rpy="0 0 0" />
      <geometry>
        <mesh filename="meshes/L_index_proximal.STL" />
      </geometry>
    </collision>
  </link>
  <joint name="L_index_MCP_joint" type="revolute">
    <origin xyz="0.0269420472022218 0.00950000000154763 -0.114975331627829" rpy="0 -0.0523598774782631 0" />
    <parent link="LeftHand" />
    <child link="L_index_proximal" />
    <axis xyz="-1 0 0" />
    <limit lower="0" upper="1.7" effort="1" velocity="1" />
  </joint>
  <link name="L_index_distal">
    <inertial>
      <origin xyz="0.00000000 0.00168954 -0.01536935" rpy="0 0 0" />
      <mass value="0.00905901" />
      <inertia ixx="0.00000173" ixy="0.00000000" ixz="0.00000000" iyy="0.00000168" iyz="0.00000025" izz="0.00000025" />
    </inertial>
    <visual>
      <origin xyz="0 0 0" rpy="0 0 0" />
      <geometry>
        <mesh filename="meshes/L_index_distal.STL" />
      </geometry>
      <material name="">
        <color rgba="0.752941176470588 0.752941176470588 0.752941176470588 1" />
      </material>
    </visual>
    <collision>
      <origin xyz="0 0 0" rpy="0 0 0" />
      <geometry>
        <mesh filename="meshes/L_index_distal.STL" />
      </geometry>
    </collision>
  </link>
  <joint name="L_index_DIP_joint" type="revolute">
    <origin xyz="0 -0.00111268989731944 -0.0319806491677784" rpy="0 0 0" />
    <parent link="L_index_proximal" />
    <child link="L_index_distal" />
    <axis xyz="-1 0 0" />
    <limit lower="0" upper="1.6" effort="1" velocity="1" />
  </joint>

  <!-- 左手中指 -->
  <link name="L_middle_proximal">
    <inertial>
      <origin xyz="0.00000000 0.00115546 -0.01334192" rpy="0 0 0" />
      <mass value="0.01313099" />
      <inertia ixx="0.00000194" ixy="0.00000000" ixz="0.00000000" iyy="0.00000193" iyz="0.00000010" izz="0.00000054" />
    </inertial>
    <visual>
      <origin xyz="0 0 0" rpy="0 0 0" />
      <geometry>
        <mesh filename="meshes/L_middle_proximal.STL" />
      </geometry>
      <material name="">
        <color rgba="0.752941176470588 0.752941176470588 0.752941176470588 1" />
      </material>
    </visual>
    <collision>
      <origin xyz="0 0 0" rpy="0 0 0" />
      <geometry>
        <mesh filename="meshes/L_middle_proximal.STL" />
      </geometry>
    </collision>
  </link>
  <joint name="L_middle_MCP_joint" type="revolute">
    <origin xyz="0.00799999998838565 0.0144999999999475 -0.128000000000728" rpy="0 0 0" />
    <parent link="LeftHand" />
    <child link="L_middle_proximal" />
    <axis xyz="-1 0 0" />
    <limit lower="0" upper="1.7" effort="1" velocity="1" />
  </joint>
  <link name="L_middle_distal">
    <inertial>
      <origin xyz="0.00000000 -0.00003933 -0.01546189" rpy="0 0 0" />
      <mass value="0.00905901" />
      <inertia ixx="0.00000173" ixy="0.00000000" ixz="0.00000000" iyy="0.00000161" iyz="0.00000040" izz="0.00000032" />
    </inertial>
    <visual>
      <origin xyz="0 0 0" rpy="0 0 0" />
      <geometry>
        <mesh filename="meshes/L_middle_distal.STL" />
      </geometry>
      <material name="">
        <color rgba="0.752941176470588 0.752941176470588 0.752941176470588 1" />
      </material>
    </visual>
    <collision>
      <origin xyz="0 0 0" rpy="0 0 0" />
      <geometry>
        <mesh filename="meshes/L_middle_distal.STL" />
      </geometry>
    </collision>
  </link>
  <joint name="L_middle_DIP_joint" type="revolute">
    <origin xyz="0 -0.00293735370583337 -0.0318649015879072" rpy="0 0 0" />
    <parent link="L_middle_proximal" />
    <child link="L_middle_distal" />
    <axis xyz="-1 0 0" />
    <limit lower="0" upper="1.6" effort="1" velocity="1" />
  </joint>

  <!-- 左手无名指 -->
  <link name="L_ring_proximal">
    <inertial>
      <origin xyz="-0.00000395 0.00199338 -0.01313108" rpy="0 0 0" />
      <mass value="0.01454111" />
      <inertia ixx="0.00000195" ixy="0.00000000" ixz="0.00000000" iyy="0.00000195" iyz="0.00000002" izz="0.00000054" />
    </inertial>
    <visual>
      <origin xyz="0 0 0" rpy="0 0 0" />
      <geometry>
        <mesh filename="meshes/L_ring_proximal.STL" />
      </geometry>
      <material name="">
        <color rgba="0.752941176470588 0.752941176470588 0.752941176470588 1" />
      </material>
    </visual>
    <collision>
      <origin xyz="0 0 0" rpy="0 0 0" />
      <geometry>
        <mesh filename="meshes/L_ring_proximal.STL" />
      </geometry>
    </collision>
  </link>
  <joint name="L_ring_MCP_joint" type="revolute">
    <origin xyz="-0.0109420472229284 0.00949999999845705 -0.119975331624717" rpy="0 0.052359877641387 0" />
    <parent link="LeftHand" />
    <child link="L_ring_proximal" />
    <axis xyz="-1 0 0" />
    <limit lower="0" upper="1.7" effort="1" velocity="1" />
  </joint>
  <link name="L_ring_distal">
    <inertial>
      <origin xyz="0.00000000 0.00168954 -0.01536935" rpy="0 0 0" />
      <mass value="0.00905901" />
      <inertia ixx="0.00000173" ixy="0.00000000" ixz="0.00000000" iyy="0.00000168" iyz="0.00000025" izz="0.00000025" />
    </inertial>
    <visual>
      <origin xyz="0 0 0" rpy="0 0 0" />
      <geometry>
        <mesh filename="meshes/L_ring_distal.STL" />
      </geometry>
      <material name="">
        <color rgba="0.752941176470588 0.752941176470588 0.752941176470588 1" />
      </material>
    </visual>
    <collision>
      <origin xyz="0 0 0" rpy="0 0 0" />
      <geometry>
        <mesh filename="meshes/L_ring_distal.STL" />
      </geometry>
    </collision>
  </link>
  <joint name="L_ring_DIP_joint" type="revolute">
    <origin xyz="0 -0.00111268989759014 -0.0319806491677691" rpy="0 0 0" />
    <parent link="L_ring_proximal" />
    <child link="L_ring_distal" />
    <axis xyz="-1 0 0" />
    <limit lower="0" upper="1.6" effort="1" velocity="1" />
  </joint>

  <!-- 左手小指 -->
  <link name="L_pinky_proximal">
    <inertial>
      <origin xyz="0.00000000 0.00191043 -0.01322575" rpy="0 0 0" />
      <mass value="0.01313099" />
      <inertia ixx="0.00000194" ixy="0.00000000" ixz="0.00000000" iyy="0.00000194" iyz="0.00000002" izz="0.00000053" />
    </inertial>
    <visual>
      <origin xyz="0 0 0" rpy="0 0 0" />
      <geometry>
        <mesh filename="meshes/L_pinky_proximal.STL" />
      </geometry>
      <material name="">
        <color rgba="0.752941176470588 0.752941176470588 0.752941176470588 1" />
      </material>
    </visual>
    <collision>
      <origin xyz="0 0 0" rpy="0 0 0" />
      <geometry>
        <mesh filename="meshes/L_pinky_proximal.STL" />
      </geometry>
    </collision>
  </link>
  <joint name="L_pinky_MCP_joint" type="revolute">
    <origin xyz="-0.0301936481908677 0.00449999999694281 -0.11286583072711" rpy="0 0.12217304772112 0" />
    <parent link="LeftHand" />
    <child link="L_pinky_proximal" />
    <axis xyz="-1 0 0" />
    <limit lower="0" upper="1.7" effort="1" velocity="1" />
  </joint>
  <link name="L_pinky_distal">
    <inertial>
      <origin xyz="0.00000199 0.00260409 -0.01099907" rpy="0 0 0" />
      <mass value="0.00693901" />
      <inertia ixx="0.00000086" ixy="0.00000000" ixz="0.00000000" iyy="0.00000084" iyz="0.00000010" izz="0.00000016" />
    </inertial>
    <visual>
      <origin xyz="0 0 0" rpy="0 0 0" />
      <geometry>
        <mesh filename="meshes/L_pinky_distal.STL" />
      </geometry>
      <material name="">
        <color rgba="0.752941176470588 0.752941176470588 0.752941176470588 1" />
      </material>
    </visual>
    <collision>
      <origin xyz="0 0 0" rpy="0 0 0" />
      <geometry>
        <mesh filename="meshes/L_pinky_distal.STL" />
      </geometry>
    </collision>
  </link>
  <joint name="L_pinky_DIP_joint" type="revolute">
    <origin xyz="0 -0.00111268989776986 -0.0319806491677628" rpy="0 0 0" />
    <parent link="L_pinky_proximal" />
    <child link="L_pinky_distal" />
    <axis xyz="-1 0 0" />
    <limit lower="0" upper="1.6" effort="1" velocity="1" />
  </joint>

  <!-- 右手手腕 -->
  <link name="RightHand">
    <inertial>
      <origin xyz="-0.00030616 -0.00861825 -0.06634429" rpy="0 0 0" />
      <mass value="0.35815530" />
      <inertia ixx="0.00032078" ixy="-0.00001180" ixz="-0.00000453" iyy="0.00043005" iyz="0.00002137" izz="0.00018497" />
    </inertial>
    <visual>
      <origin xyz="0 0 0" rpy="0 0 0" />
      <geometry>
        <mesh filename="meshes/wristRollRight.STL" />
      </geometry>
      <material name="">
        <color rgba="0.752941176470588 0.752941176470588 0.752941176470588 1" />
      </material>
    </visual>
    <collision>
      <origin xyz="0 0 0" rpy="0 0 0" />
      <geometry>
        <mesh filename="meshes/wristRollRight.STL" />
      </geometry>
    </collision>
  </link>

  <!-- 右手拇指 -->
  <link name="R_thumb_proximal_base">
    <inertial>
      <origin xyz="0.00431634 -0.00026726 -0.00141884" rpy="0 0 0" />
      <mass value="0.00893190" />
      <inertia ixx="0.00000031" ixy="0.00000008" ixz="-0.00000006" iyy="0.00000055" iyz="-0.00000001" izz="0.00000046" />
    </inertial>
    <visual>
      <origin xyz="0 0 0" rpy="0 0 0" />
      <geometry>
        <mesh filename="meshes/R_thumb_proximal_base.STL" />
      </geometry>
      <material name="">
        <color rgba="0.752941176470588 0.752941176470588 0.752941176470588 1" />
      </material>
    </visual>
    <collision>
      <origin xyz="0 0 0" rpy="0 0 0" />
      <geometry>
        <mesh filename="meshes/R_thumb_proximal_base.STL" />
      </geometry>
    </collision>
  </link>
  <joint name="R_thumb_MCP_joint1" type="revolute">
    <origin xyz="0.0244999999998152 0.0100000000000263 -0.0470000000000906" rpy="0 0 0" />
    <parent link="RightHand" />
    <child link="R_thumb_proximal_base" />
    <axis xyz="0 0 1" />
    <limit lower="0" upper="1.1" effort="1" velocity="1" />
  </joint>
  <link name="R_thumb_proximal">
    <inertial>
      <origin xyz="0.02369685 0.00000000 -0.01467226" rpy="0 0 0" />
      <mass value="0.06158426" />
      <inertia ixx="0.00001171" ixy="0.00000000" ixz="-0.00000575" iyy="0.00002013" iyz="0.00000000" izz="0.00001139" />
    </inertial>
    <visual>
      <origin xyz="0 0 0" rpy="0 0 0" />
      <geometry>
        <mesh filename="meshes/R_thumb_proximal.STL" />
      </geometry>
      <material name="">
        <color rgba="0.752941176470588 0.752941176470588 0.752941176470588 1" />
      </material>
    </visual>
    <collision>
      <origin xyz="0 0 0" rpy="0 0 0" />
      <geometry>
        <mesh filename="meshes/R_thumb_proximal.STL" />
      </geometry>
    </collision>
  </link>
  <joint name="R_thumb_MCP_joint2" type="revolute">
    <origin xyz="0.0119540024564323 0.00104967865159283 0" rpy="0 0 0.0875851579817108" />
    <parent link="R_thumb_proximal_base" />
    <child link="R_thumb_proximal" />
    <axis xyz="0 1 0" />
    <limit lower="0" upper="0.5" effort="1" velocity="1" />
  </joint>
  <link name="R_thumb_intermediate">
    <inertial>
      <origin xyz="0.00973134 0.00000000 -0.00266467" rpy="0 0 0" />
      <mass value="0.01538338" />
      <inertia ixx="0.00000142" ixy="0.00000000" ixz="-0.00000039" iyy="0.00000172" iyz="0.00000000" izz="0.00000100" />
    </inertial>
    <visual>
      <origin xyz="0 0 0" rpy="0 0 0" />
      <geometry>
        <mesh filename="meshes/R_thumb_intermediate.STL" />
      </geometry>
      <material name="">
        <color rgba="0.752941176470588 0.752941176470588 0.752941176470588 1" />
      </material>
    </visual>
    <collision>
      <origin xyz="0 0 0" rpy="0 0 0" />
      <geometry>
        <mesh filename="meshes/R_thumb_intermediate.STL" />
      </geometry>
    </collision>
  </link>
  <joint name="R_thumb_PIP_joint" type="revolute">
    <origin xyz="0.044288564116179 0 -0.0376632856841606" rpy="0 0 0" />
    <parent link="R_thumb_proximal" />
    <child link="R_thumb_intermediate" />
    <axis xyz="0 1 0" />
    <limit lower="0" upper="1" effort="1" velocity="1" />
  </joint>
  <link name="R_thumb_distal">
    <inertial>
      <origin xyz="0.00714151 0.00000139 -0.00689413" rpy="0 0 0" />
      <mass value="0.01043741" />
      <inertia ixx="0.00000076" ixy="0.00000000" ixz="-0.00000020" iyy="0.00000086" iyz="0.00000000" izz="0.00000052" />
    </inertial>
    <visual>
      <origin xyz="0 0 0" rpy="0 0 0" />
      <geometry>
        <mesh filename="meshes/R_thumb_distal.STL" />
      </geometry>
      <material name="">
        <color rgba="0.752941176470588 0.752941176470588 0.752941176470588 1" />
      </material>
    </visual>
    <collision>
      <origin xyz="0 0 0" rpy="0 0 0" />
      <geometry>
        <mesh filename="meshes/R_thumb_distal.STL" />
      </geometry>
    </collision>
  </link>
  <joint name="R_thumb_DIP_joint" type="revolute">
    <origin xyz="0.0164679343353944 0 -0.0154614727217485" rpy="0 0 0" />
    <parent link="R_thumb_intermediate" />
    <child link="R_thumb_distal" />
    <axis xyz="0 1 0" />
    <limit lower="0" upper="1.2" effort="1" velocity="1" />
  </joint>

  <!-- 右手食指 -->
  <link name="R_index_proximal">
    <inertial>
      <origin xyz="0.00000000 -0.00199820 -0.01311710" rpy="0 0 0" />
      <mass value="0.01454119" />
      <inertia ixx="0.00000195" ixy="0.00000000" ixz="0.00000000" iyy="0.00000195" iyz="-0.00000002" izz="0.00000054" />
    </inertial>
    <visual>
      <origin xyz="0 0 0" rpy="0 0 0" />
      <geometry>
        <mesh filename="meshes/R_index_proximal.STL" />
      </geometry>
      <material name="">
        <color rgba="0.752941176470588 0.752941176470588 0.752941176470588 1" />
      </material>
    </visual>
    <collision>
      <origin xyz="0 0 0" rpy="0 0 0" />
      <geometry>
        <mesh filename="meshes/R_index_proximal.STL" />
      </geometry>
    </collision>
  </link>
  <joint name="R_index_MCP_joint" type="revolute">
    <origin xyz="0.0269420472120735 -0.00950000000009146 -0.114975331625641" rpy="0 -0.0523598775568891 0" />
    <parent link="RightHand" />
    <child link="R_index_proximal" />
    <axis xyz="1 0 0" />
    <limit lower="0" upper="1.7" effort="1" velocity="1" />
  </joint>
  <link name="R_index_distal">
    <inertial>
      <origin xyz="0.00000000 -0.00168936 -0.01536965" rpy="0 0 0" />
      <mass value="0.00905901" />
      <inertia ixx="0.00000173" ixy="0.00000000" ixz="0.00000000" iyy="0.00000168" iyz="-0.00000025" izz="0.00000025" />
    </inertial>
    <visual>
      <origin xyz="0 0 0" rpy="0 0 0" />
      <geometry>
        <mesh filename="meshes/R_index_distal.STL" />
      </geometry>
      <material name="">
        <color rgba="0.752941176470588 0.752941176470588 0.752941176470588 1" />
      </material>
    </visual>
    <collision>
      <origin xyz="0 0 0" rpy="0 0 0" />
      <geometry>
        <mesh filename="meshes/R_index_distal.STL" />
      </geometry>
    </collision>
  </link>
  <joint name="R_index_DIP_joint" type="revolute">
    <origin xyz="0 0.00111268989722751 -0.0319806491677816" rpy="0 0 0" />
    <parent link="R_index_proximal" />
    <child link="R_index_distal" />
    <axis xyz="1 0 0" />
    <limit lower="0" upper="1.6" effort="1" velocity="1" />
  </joint>

  <!-- 右手中指 -->
  <link name="R_middle_proximal">
    <inertial>
      <origin xyz="0.00000000 -0.00115549 -0.01334194" rpy="0 0 0" />
      <mass value="0.01313107" />
      <inertia ixx="0.00000194" ixy="0.00000000" ixz="0.00000000" iyy="0.00000193" iyz="-0.00000010" izz="0.00000054" />
    </inertial>
    <visual>
      <origin xyz="0 0 0" rpy="0 0 0" />
      <geometry>
        <mesh filename="meshes/R_middle_proximal.STL" />
      </geometry>
      <material name="">
        <color rgba="0.752941176470588 0.752941176470588 0.752941176470588 1" />
      </material>
    </visual>
    <collision>
      <origin xyz="0 0 0" rpy="0 0 0" />
      <geometry>
        <mesh filename="meshes/R_middle_proximal.STL" />
      </geometry>
    </collision>
  </link>
  <joint name="R_middle_MCP_joint" type="revolute">
    <origin xyz="0.00799999999968861 -0.0145000000002054 -0.127999999999992" rpy="0 0 0" />
    <parent link="RightHand" />
    <child link="R_middle_proximal" />
    <axis xyz="1 0 0" />
    <limit lower="0" upper="1.7" effort="1" velocity="1" />
  </joint>
  <link name="R_middle_distal">
    <inertial>
      <origin xyz="0.00000000 0.00003955 -0.01546217" rpy="0 0 0" />
      <mass value="0.00905901" />
      <inertia ixx="0.00000173" ixy="0.00000000" ixz="0.00000000" iyy="0.00000161" iyz="-0.00000040" izz="0.00000032" />
    </inertial>
    <visual>
      <origin xyz="0 0 0" rpy="0 0 0" />
      <geometry>
        <mesh filename="meshes/R_middle_distal.STL" />
      </geometry>
      <material name="">
        <color rgba="0.752941176470588 0.752941176470588 0.752941176470588 1" />
      </material>
    </visual>
    <collision>
      <origin xyz="0 0 0" rpy="0 0 0" />
      <geometry>
        <mesh filename="meshes/R_middle_distal.STL" />
      </geometry>
    </collision>
  </link>
  <joint name="R_middle_DIP_joint" type="revolute">
    <origin xyz="0 0.00293735370559906 -0.0318649015879289" rpy="0 0 0" />
    <parent link="R_middle_proximal" />
    <child link="R_middle_distal" />
    <axis xyz="1 0 0" />
    <limit lower="0" upper="1.6" effort="1" velocity="1" />
  </joint>

  <!-- 右手无名指 -->
  <link name="R_ring_proximal">
    <inertial>
      <origin xyz="0.00000000 -0.00199820 -0.01311710" rpy="0 0 0" />
      <mass value="0.01454119" />
      <inertia ixx="0.00000195" ixy="0.00000000" ixz="0.00000000" iyy="0.00000195" iyz="-0.00000002" izz="0.00000054" />
    </inertial>
    <visual>
      <origin xyz="0 0 0" rpy="0 0 0" />
      <geometry>
        <mesh filename="meshes/R_ring_proximal.STL" />
      </geometry>
      <material name="">
        <color rgba="0.752941176470588 0.752941176470588 0.752941176470588 1" />
      </material>
    </visual>
    <collision>
      <origin xyz="0 0 0" rpy="0 0 0" />
      <geometry>
        <mesh filename="meshes/R_ring_proximal.STL" />
      </geometry>
    </collision>
  </link>
  <joint name="R_ring_MCP_joint" type="revolute">
    <origin xyz="-0.0109420472126836 -0.00950000000027432 -0.119975331625507" rpy="0 0.0523598775627611 0" />
    <parent link="RightHand" />
    <child link="R_ring_proximal" />
    <axis xyz="1 0 0" />
    <limit lower="0" upper="1.7" effort="1" velocity="1" />
  </joint>
  <link name="R_ring_distal">
    <inertial>
      <origin xyz="0.00000000 -0.00168936 -0.01536965" rpy="0 0 0" />
      <mass value="0.00905901" />
      <inertia ixx="0.00000173" ixy="0.00000000" ixz="0.00000000" iyy="0.00000168" iyz="-0.00000025" izz="0.00000025" />
    </inertial>
    <visual>
      <origin xyz="0 0 0" rpy="0 0 0" />
      <geometry>
        <mesh filename="meshes/R_ring_distal.STL" />
      </geometry>
      <material name="">
        <color rgba="0.752941176470588 0.752941176470588 0.752941176470588 1" />
      </material>
    </visual>
    <collision>
      <origin xyz="0 0 0" rpy="0 0 0" />
      <geometry>
        <mesh filename="meshes/R_ring_distal.STL" />
      </geometry>
    </collision>
  </link>
  <joint name="R_ring_DIP_joint" type="revolute">
    <origin xyz="0 0.00111268989721214 -0.0319806491677822" rpy="0 0 0" />
    <parent link="R_ring_proximal" />
    <child link="R_ring_distal" />
    <axis xyz="1 0 0" />
    <limit lower="0" upper="1.6" effort="1" velocity="1" />
  </joint>

  <!-- 右手小指 -->
  <link name="R_pinky_proximal">
    <inertial>
      <origin xyz="0.00000000 -0.00191046 -0.01322577" rpy="0 0 0" />
      <mass value="0.01313107" />
      <inertia ixx="0.00000194" ixy="0.00000000" ixz="0.00000000" iyy="0.00000194" iyz="-0.00000002" izz="0.00000053" />
    </inertial>
    <visual>
      <origin xyz="0 0 0" rpy="0 0 0" />
      <geometry>
        <mesh filename="meshes/R_pinky_proximal.STL" />
      </geometry>
      <material name="">
        <color rgba="0.752941176470588 0.752941176470588 0.752941176470588 1" />
      </material>
    </visual>
    <collision>
      <origin xyz="0 0 0" rpy="0 0 0" />
      <geometry>
        <mesh filename="meshes/R_pinky_proximal.STL" />
      </geometry>
    </collision>
  </link>
  <joint name="R_pinky_MCP_joint" type="revolute">
    <origin xyz="-0.0301936481816091 -0.00450000000035261 -0.112865830729451" rpy="0 0.122173047642494 0" />
    <parent link="RightHand" />
    <child link="R_pinky_proximal" />
    <axis xyz="1 0 0" />
    <limit lower="0" upper="1.7" effort="1" velocity="1" />
  </joint>
  <link name="R_pinky_distal">
    <inertial>
      <origin xyz="0.00000201 -0.00260417 -0.01099890" rpy="0 0 0" />
      <mass value="0.00693901" />
      <inertia ixx="0.00000086" ixy="0.00000000" ixz="0.00000000" iyy="0.00000084" iyz="-0.00000010" izz="0.00000016" />
    </inertial>
    <visual>
      <origin xyz="0 0 0" rpy="0 0 0" />
      <geometry>
        <mesh filename="meshes/R_pinky_distal.STL" />
      </geometry>
      <material name="">
        <color rgba="0.752941176470588 0.752941176470588 0.752941176470588 1" />
      </material>
    </visual>
    <collision>
      <origin xyz="0 0 0" rpy="0 0 0" />
      <geometry>
        <mesh filename="meshes/R_pinky_distal.STL" />
      </geometry>
    </collision>
  </link>
  <joint name="R_pinky_DIP_joint" type="revolute">
    <origin xyz="0 0.00111268989720342 -0.0319806491677825" rpy="0 0 0" />
    <parent link="R_pinky_proximal" />
    <child link="R_pinky_distal" />
    <axis xyz="1 0 0" />
    <limit lower="0" upper="1.6" effort="1" velocity="1" />
  </joint>
</robot>
